Workbook

Sheet README
A1: NileCare – ISO/IEC 27001:2022 Annex A Gap Assessment
A3: Scope | B3: All 93 Annex A controls (2022 edition), assessed against the fictional company NileCare (private clinics, Cairo, ~120 staff).
A4: Scoring | B4: Implemented = 1, Partially implemented = 0.5, Not implemented = 0. Not applicable controls are excluded from the percentage.
A5: Compliance % | B5: Sum of scores divided by number of applicable controls. A simple maturity indicator, not a certification result.
A6: Link to risks | B6: The 'Related Risks' column points to Risk IDs in the NileCare Risk Register workbook.
A7: Legend | B7: Blue text = input (edit these). Black text = formulas.
A8: Assumptions | B8: All findings are invented for practice. Statuses were set to be consistent with the risk register (e.g. no MFA, untested backups, no SIEM). Controls 8.4 and 8.25 are not applicable because NileCare has no in-house development; the booking portal is built by an external agency.

Sheet Gap Assessment
A1: Control ID | B1: Control | C1: Theme | D1: Status | E1: Score (auto) | F1: Current State | G1: Gap / Recommended Action | H1: Priority | I1: Owner | J1: Related Risks
A2: 5.1 | B2: Policies for information security | C2: Organizational | D2: Partially implemented | E2: =IF(D2="Implemented",1,IF(D2="Partially implemented",0.5,IF(D2="Not implemented",0,""))) -> 0.5 | F2: Short IT usage policy exists; no approved ISMS policy set | G2: Approve top-level information security policy and topic-specific policies; review yearly | H2: High | I2: IT Manager
A3: 5.2 | B3: Information security roles and responsibilities | C3: Organizational | D3: Not implemented | E3: =IF(D3="Implemented",1,IF(D3="Partially implemented",0.5,IF(D3="Not implemented",0,""))) -> 0 | F3: Security duties not formally assigned | G3: Define ISMS roles and owners in a RACI matrix | H3: High | I3: IT Manager
A4: 5.3 | B4: Segregation of duties | C4: Organizational | D4: Partially implemented | E4: =IF(D4="Implemented",1,IF(D4="Partially implemented",0.5,IF(D4="Not implemented",0,""))) -> 0.5 | F4: Finance approvals are segregated; IT admins can request and approve access | G4: Separate access request and approval | H4: Medium | I4: IT Manager
A5: 5.4 | B5: Management responsibilities | C5: Organizational | D5: Partially implemented | E5: =IF(D5="Implemented",1,IF(D5="Partially implemented",0.5,IF(D5="Not implemented",0,""))) -> 0.5 | F5: Management supports IT but no security objectives set | G5: Set security objectives; hold quarterly management review | H5: Medium | I5: IT Manager
A6: 5.5 | B6: Contact with authorities | C6: Organizational | D6: Not implemented | E6: =IF(D6="Implemented",1,IF(D6="Partially implemented",0.5,IF(D6="Not implemented",0,""))) -> 0 | F6: No contact list for authorities | G6: Keep contacts for EG-CERT, data protection authority and cyber police | H6: Low | I6: IT Manager
A7: 5.6 | B7: Contact with special interest groups | C7: Organizational | D7: Not implemented | E7: =IF(D7="Implemented",1,IF(D7="Partially implemented",0.5,IF(D7="Not implemented",0,""))) -> 0 | F7: No participation in security communities | G7: Join EG-CERT bulletins and healthcare security groups | H7: Low | I7: IT Manager
A8: 5.7 | B8: Threat intelligence | C8: Organizational | D8: Not implemented | E8: =IF(D8="Implemented",1,IF(D8="Partially implemented",0.5,IF(D8="Not implemented",0,""))) -> 0 | F8: No threat intelligence used | G8: Subscribe to EG-CERT and vendor advisories; review monthly | H8: Medium | I8: IT Manager
A9: 5.8 | B9: Information security in project management | C9: Organizational | D9: Not implemented | E9: =IF(D9="Implemented",1,IF(D9="Partially implemented",0.5,IF(D9="Not implemented",0,""))) -> 0 | F9: Security not part of IT project steps | G9: Add a security checklist to every IT project | H9: Low | I9: IT Manager
A10: 5.9 | B10: Inventory of information and other associated assets | C10: Organizational | D10: Partially implemented | E10: =IF(D10="Implemented",1,IF(D10="Partially implemented",0.5,IF(D10="Not implemented",0,""))) -> 0.5 | F10: Asset inventory created in this project; no maintenance process yet | G10: Assign owners and review the inventory twice a year | H10: Medium | I10: IT Manager
A11: 5.10 | B11: Acceptable use of information and other associated assets | C11: Organizational | D11: Partially implemented | E11: =IF(D11="Implemented",1,IF(D11="Partially implemented",0.5,IF(D11="Not implemented",0,""))) -> 0.5 | F11: Acceptable use text in handbook; not signed by staff | G11: Sign acceptable use policy at onboarding | H11: Low | I11: HR Manager
A12: 5.11 | B12: Return of assets | C12: Organizational | D12: Partially implemented | E12: =IF(D12="Implemented",1,IF(D12="Partially implemented",0.5,IF(D12="Not implemented",0,""))) -> 0.5 | F12: Laptops collected on exit; tokens and accounts not always | G12: Add return of assets to offboarding checklist | H12: Low | I12: HR Manager
A13: 5.12 | B13: Classification of information | C13: Organizational | D13: Not implemented | E13: =IF(D13="Implemented",1,IF(D13="Partially implemented",0.5,IF(D13="Not implemented",0,""))) -> 0 | F13: No classification scheme | G13: Adopt 4 levels: Public, Internal, Confidential, Patient-Restricted | H13: Medium | I13: Head of Medical Operations | J13: R-12
A14: 5.13 | B14: Labelling of information | C14: Organizational | D14: Not implemented | E14: =IF(D14="Implemented",1,IF(D14="Partially implemented",0.5,IF(D14="Not implemented",0,""))) -> 0 | F14: No labelling of documents or reports | G14: Label documents by classification after 5.12 is approved | H14: Low | I14: IT Manager
A15: 5.14 | B15: Information transfer | C15: Organizational | D15: Partially implemented | E15: =IF(D15="Implemented",1,IF(D15="Partially implemented",0.5,IF(D15="Not implemented",0,""))) -> 0.5 | F15: Patient reports sometimes sent by email; no secure transfer rules | G15: Define secure transfer channels and encrypted email for patient data | H15: Medium | I15: IT Manager
A16: 5.15 | B16: Access control | C16: Organizational | D16: Partially implemented | E16: =IF(D16="Implemented",1,IF(D16="Partially implemented",0.5,IF(D16="Not implemented",0,""))) -> 0.5 | F16: AD groups exist; no approved access control policy | G16: Approve access control policy (see Access_Control_Policy.md) | H16: High | I16: IT Manager | J16: R-02
A17: 5.16 | B17: Identity management | C17: Organizational | D17: Partially implemented | E17: =IF(D17="Implemented",1,IF(D17="Partially implemented",0.5,IF(D17="Not implemented",0,""))) -> 0.5 | F17: Unique IDs for staff; shared accounts at some reception desks | G17: Remove shared accounts; link IDs to HR records | H17: High | I17: IT Manager | J17: R-02
A18: 5.17 | B18: Authentication information | C18: Organizational | D18: Partially implemented | E18: =IF(D18="Implemented",1,IF(D18="Partially implemented",0.5,IF(D18="Not implemented",0,""))) -> 0.5 | F18: Password policy exists; MFA not enforced | G18: Enforce MFA and password manager guidance | H18: High | I18: IT Manager
A19: 5.18 | B19: Access rights | C19: Organizational | D19: Partially implemented | E19: =IF(D19="Implemented",1,IF(D19="Partially implemented",0.5,IF(D19="Not implemented",0,""))) -> 0.5 | F19: No periodic access review; leavers sometimes delayed | G19: Quarterly access reviews; same-day removal for leavers | H19: High | I19: IT Manager | J19: R-02
A20: 5.19 | B20: Information security in supplier relationships | C20: Organizational | D20: Not implemented | E20: =IF(D20="Implemented",1,IF(D20="Partially implemented",0.5,IF(D20="Not implemented",0,""))) -> 0 | F20: No supplier security requirements or register | G20: Create supplier register with risk tier and requirements | H20: High | I20: Procurement Manager | J20: R-06
A21: 5.20 | B21: Addressing information security within supplier agreements | C21: Organizational | D21: Not implemented | E21: =IF(D21="Implemented",1,IF(D21="Partially implemented",0.5,IF(D21="Not implemented",0,""))) -> 0 | F21: EMR vendor contract covers uptime only | G21: Add security and breach-notification clauses to vendor contracts | H21: High | I21: Procurement Manager | J21: R-06
A22: 5.21 | B22: Managing information security in the ICT supply chain | C22: Organizational | D22: Not implemented | E22: =IF(D22="Implemented",1,IF(D22="Partially implemented",0.5,IF(D22="Not implemented",0,""))) -> 0 | F22: Hardware and software suppliers not assessed | G22: Include supply chain requirements in procurement | H22: Medium | I22: Procurement Manager
A23: 5.22 | B23: Monitoring, review and change management of supplier services | C23: Organizational | D23: Not implemented | E23: =IF(D23="Implemented",1,IF(D23="Partially implemented",0.5,IF(D23="Not implemented",0,""))) -> 0 | F23: No supplier reviews | G23: Annual supplier security review for critical vendors | H23: Medium | I23: Procurement Manager
A24: 5.23 | B24: Information security for use of cloud services | C24: Organizational | D24: Not implemented | E24: =IF(D24="Implemented",1,IF(D24="Partially implemented",0.5,IF(D24="Not implemented",0,""))) -> 0 | F24: EMR and email are cloud-based; no cloud policy or exit plan | G24: Cloud usage policy with shared responsibility and exit plan | H24: High | I24: IT Manager | J24: R-06
A25: 5.24 | B25: Information security incident management planning and preparation | C25: Organizational | D25: Not implemented | E25: =IF(D25="Implemented",1,IF(D25="Partially implemented",0.5,IF(D25="Not implemented",0,""))) -> 0 | F25: No incident response plan | G25: Approve incident response policy and playbooks (see Incident_Response_Policy.md) | H25: High | I25: IT Manager
A26: 5.25 | B26: Assessment and decision on information security events | C26: Organizational | D26: Not implemented | E26: =IF(D26="Implemented",1,IF(D26="Partially implemented",0.5,IF(D26="Not implemented",0,""))) -> 0 | F26: No triage criteria | G26: Define severity levels and escalation path | H26: Medium | I26: IT Manager
A27: 5.26 | B27: Response to information security incidents | C27: Organizational | D27: Partially implemented | E27: =IF(D27="Implemented",1,IF(D27="Partially implemented",0.5,IF(D27="Not implemented",0,""))) -> 0.5 | F27: IT fixes issues ad hoc; no defined response steps | G27: Use documented response phases and roles | H27: High | I27: IT Manager
A28: 5.27 | B28: Learning from information security incidents | C28: Organizational | D28: Not implemented | E28: =IF(D28="Implemented",1,IF(D28="Partially implemented",0.5,IF(D28="Not implemented",0,""))) -> 0 | F28: No post-incident reviews | G28: Hold a review after each major incident and track actions | H28: Medium | I28: IT Manager
A29: 5.28 | B29: Collection of evidence | C29: Organizational | D29: Not implemented | E29: =IF(D29="Implemented",1,IF(D29="Partially implemented",0.5,IF(D29="Not implemented",0,""))) -> 0 | F29: No evidence handling procedure | G29: Define log and disk evidence preservation steps | H29: Low | I29: IT Manager
A30: 5.29 | B30: Information security during disruption | C30: Organizational | D30: Not implemented | E30: =IF(D30="Implemented",1,IF(D30="Partially implemented",0.5,IF(D30="Not implemented",0,""))) -> 0 | F30: Security controls not planned for outages | G30: Define minimum security controls during disruption | H30: Medium | I30: IT Manager
A31: 5.30 | B31: ICT readiness for business continuity | C31: Organizational | D31: Partially implemented | E31: =IF(D31="Implemented",1,IF(D31="Partially implemented",0.5,IF(D31="Not implemented",0,""))) -> 0.5 | F31: Backups exist; no tested DR or continuity plan | G31: Create DR plan with recovery targets; test yearly | H31: High | I31: IT Manager | J31: R-04, R-08
A32: 5.31 | B32: Legal, statutory, regulatory and contractual requirements | C32: Organizational | D32: Partially implemented | E32: =IF(D32="Implemented",1,IF(D32="Partially implemented",0.5,IF(D32="Not implemented",0,""))) -> 0.5 | F32: Aware of Egypt PDPL (Law 151 of 2020); no requirements register | G32: Maintain legal requirements register; appoint DPO | H32: High | I32: Legal and Compliance | J32: R-14
A33: 5.32 | B33: Intellectual property rights | C33: Organizational | D33: Partially implemented | E33: =IF(D33="Implemented",1,IF(D33="Partially implemented",0.5,IF(D33="Not implemented",0,""))) -> 0.5 | F33: Clinical systems licensed; workstation software not fully tracked | G33: Software license inventory and audit | H33: Low | I33: IT Manager
A34: 5.33 | B34: Protection of records | C34: Organizational | D34: Partially implemented | E34: =IF(D34="Implemented",1,IF(D34="Partially implemented",0.5,IF(D34="Not implemented",0,""))) -> 0.5 | F34: Medical records follow clinical retention rules; other records have none | G34: Retention schedule for all record types | H34: Medium | I34: Legal and Compliance
A35: 5.34 | B35: Privacy and protection of PII | C35: Organizational | D35: Not implemented | E35: =IF(D35="Implemented",1,IF(D35="Partially implemented",0.5,IF(D35="Not implemented",0,""))) -> 0 | F35: No privacy notice, consent process or breach procedure | G35: Privacy notice, consent forms, data subject request and breach process | H35: High | I35: Legal and Compliance | J35: R-14
A36: 5.35 | B36: Independent review of information security | C36: Organizational | D36: Not implemented | E36: =IF(D36="Implemented",1,IF(D36="Partially implemented",0.5,IF(D36="Not implemented",0,""))) -> 0 | F36: No internal or external audit | G36: Annual internal audit against ISO 27001 | H36: Medium | I36: IT Manager
A37: 5.36 | B37: Compliance with policies, rules and standards for information security | C37: Organizational | D37: Not implemented | E37: =IF(D37="Implemented",1,IF(D37="Partially implemented",0.5,IF(D37="Not implemented",0,""))) -> 0 | F37: No compliance checks | G37: Quarterly compliance spot-checks | H37: Medium | I37: IT Manager
A38: 5.37 | B38: Documented operating procedures | C38: Organizational | D38: Partially implemented | E38: =IF(D38="Implemented",1,IF(D38="Partially implemented",0.5,IF(D38="Not implemented",0,""))) -> 0.5 | F38: Some runbooks held by individuals | G38: Centralize and version operating procedures | H38: Medium | I38: IT Manager | J38: R-16
A39: 6.1 | B39: Screening | C39: People | D39: Implemented | E39: =IF(D39="Implemented",1,IF(D39="Partially implemented",0.5,IF(D39="Not implemented",0,""))) -> 1 | F39: Background and license checks for doctors and nurses; HR checks for all hires | G39: - | H39: - | I39: HR Manager
A40: 6.2 | B40: Terms and conditions of employment | C40: People | D40: Partially implemented | E40: =IF(D40="Implemented",1,IF(D40="Partially implemented",0.5,IF(D40="Not implemented",0,""))) -> 0.5 | F40: Contracts include confidentiality; no security responsibilities clause | G40: Add information security responsibilities to contracts | H40: Low | I40: HR Manager
...

Sheet Summary
A1: Theme | B1: Total Controls | C1: Applicable | D1: Implemented | E1: Partially Implemented | F1: Not Implemented | G1: Not Applicable | H1: Compliance %
A2: Organizational | B2: =COUNTIF('Gap Assessment'!$C$2:$C$94,A2) -> 37 | C2: =B2-G2 -> 37 | D2: =COUNTIFS('Gap Assessment'!$C$2:$C$94,A2,'Gap Assessment'!$D$2:$D$94,"Implemented") -> 0 | E2: =COUNTIFS('Gap Assessment'!$C$2:$C$94,A2,'Gap Assessment'!$D$2:$D$94,"Partially implemented") -> 17 | F2: =COUNTIFS('Gap Assessment'!$C$2:$C$94,A2,'Gap Assessment'!$D$2:$D$94,"Not implemented") -> 20 | G2: =COUNTIFS('Gap Assessment'!$C$2:$C$94,A2,'Gap Assessment'!$D$2:$D$94,"Not applicable") -> 0 | H2: =IFERROR(SUMIFS('Gap Assessment'!$E$2:$E$94,'Gap Assessment'!$C$2:$C$94,A2)/C2,0) -> 0.22972973
A3: People | B3: =COUNTIF('Gap Assessment'!$C$2:$C$94,A3) -> 8 | C3: =B3-G3 -> 8 | D3: =COUNTIFS('Gap Assessment'!$C$2:$C$94,A3,'Gap Assessment'!$D$2:$D$94,"Implemented") -> 2 | E3: =COUNTIFS('Gap Assessment'!$C$2:$C$94,A3,'Gap Assessment'!$D$2:$D$94,"Partially implemented") -> 4 | F3: =COUNTIFS('Gap Assessment'!$C$2:$C$94,A3,'Gap Assessment'!$D$2:$D$94,"Not implemented") -> 2 | G3: =COUNTIFS('Gap Assessment'!$C$2:$C$94,A3,'Gap Assessment'!$D$2:$D$94,"Not applicable") -> 0 | H3: =IFERROR(SUMIFS('Gap Assessment'!$E$2:$E$94,'Gap Assessment'!$C$2:$C$94,A3)/C3,0) -> 0.5
A4: Physical | B4: =COUNTIF('Gap Assessment'!$C$2:$C$94,A4) -> 14 | C4: =B4-G4 -> 14 | D4: =COUNTIFS('Gap Assessment'!$C$2:$C$94,A4,'Gap Assessment'!$D$2:$D$94,"Implemented") -> 3 | E4: =COUNTIFS('Gap Assessment'!$C$2:$C$94,A4,'Gap Assessment'!$D$2:$D$94,"Partially implemented") -> 9 | F4: =COUNTIFS('Gap Assessment'!$C$2:$C$94,A4,'Gap Assessment'!$D$2:$D$94,"Not implemented") -> 2 | G4: =COUNTIFS('Gap Assessment'!$C$2:$C$94,A4,'Gap Assessment'!$D$2:$D$94,"Not applicable") -> 0 | H4: =IFERROR(SUMIFS('Gap Assessment'!$E$2:$E$94,'Gap Assessment'!$C$2:$C$94,A4)/C4,0) -> 0.53571429
A5: Technological | B5: =COUNTIF('Gap Assessment'!$C$2:$C$94,A5) -> 34 | C5: =B5-G5 -> 32 | D5: =COUNTIFS('Gap Assessment'!$C$2:$C$94,A5,'Gap Assessment'!$D$2:$D$94,"Implemented") -> 1 | E5: =COUNTIFS('Gap Assessment'!$C$2:$C$94,A5,'Gap Assessment'!$D$2:$D$94,"Partially implemented") -> 14 | F5: =COUNTIFS('Gap Assessment'!$C$2:$C$94,A5,'Gap Assessment'!$D$2:$D$94,"Not implemented") -> 17 | G5: =COUNTIFS('Gap Assessment'!$C$2:$C$94,A5,'Gap Assessment'!$D$2:$D$94,"Not applicable") -> 2 | H5: =IFERROR(SUMIFS('Gap Assessment'!$E$2:$E$94,'Gap Assessment'!$C$2:$C$94,A5)/C5,0) -> 0.25
A6: Total | B6: =SUM(B2:B5) -> 93 | C6: =SUM(C2:C5) -> 91 | D6: =SUM(D2:D5) -> 6 | E6: =SUM(E2:E5) -> 44 | F6: =SUM(F2:F5) -> 41 | G6: =SUM(G2:G5) -> 2 | H6: =IFERROR(SUM('Gap Assessment'!$E$2:$E$94)/C6,0) -> 0.30769231
A8: Open gaps by priority | B8: Count
A9: High | B9: =COUNTIF('Gap Assessment'!$H$2:$H$94,A9) -> 26
A10: Medium | B10: =COUNTIF('Gap Assessment'!$H$2:$H$94,A10) -> 38
A11: Low | B11: =COUNTIF('Gap Assessment'!$H$2:$H$94,A11) -> 21
A12: Total open gaps | B12: =SUM(B9:B11) -> 85
A14: Note | B14: Compliance % = (Implemented x 1 + Partially x 0.5) / Applicable controls. Priority applies to open gaps only.
